Workbook

Sheet Legend
B2: Sheet recap
B4: Name | C4: Description
B5: RAW_CEIC | C5: Raw data extracted from CEIC
B6: WIDE_CEIC | C6: CEIC data with some correction of new provinces. The island of Papua is simplified into two provinces: Papua Barat and Papua. We also add Kalimantan Utara's export and import (2010-2011) as well as Maluku Utara's export and import (from GDP, 2010-2024) manually from BPS' publication.
B7: WIDE_IDD | C7: INDODAPOER data. New provinces are reconstructed using city-level data when available, or estimated using the historical trend of their share relative to the parent province.
B8: LONG_CEIC | C8: Long format of WIDE_CEIC
B9: LONG_IBS | C9: Long format of IBS data at the province level.
B10: LONG_ALL | C10: Combined LONG_CEIC and LONG_IBS
B12: Variable recap
B14: Indicator | C14: Description | D14: Sheet | E14: Unit | F14: Source | G14: First Year | H14: Last Year | I14: Kalimantan Utara | J14: Sulawesi Barat | K14: Papua Barat | L14: Kep. Riau | M14: Maluku Utara | N14: N
B15: gdpr_ceic | C15: Gross Domestic Product: SNA 2008: 2010p | D15: WIDE_CEIC | E15: IDR bn | F15: CEIC | G15: 2000 | H15: 2025 | I15: 2010 | J15: 2005 | K15: 2002 | L15: 2003 | M15: 2000 | N15: =34*25-(I15-2000)-(J15-2000)-(K15-2000)-(L15-2000)-(M15-2000) -> 830
B16: gfcr_ceic | C16: Gross Fixed Capital Formation: SNA 2008: 2010p | D16: WIDE_CEIC | E16: IDR bn | F16: CEIC | G16: 2000 | H16: 2025 | I16: 2010 | J16: 2004 | K16: 2002 | L16: 2003 | M16: 2000 | N16: =34*25-(I16-2000)-(J16-2000)-(K16-2000)-(L16-2000)-(M16-2000) -> 831
B17: agrr_ceic | C17: Agriculture, Forestry & Fisheries: SNA 2008: 2010p | D17: WIDE_CEIC | E17: IDR bn | F17: CEIC | G17: 2000 | H17: 2025 | I17: 2010 | J17: 2005 | K17: 2002 | L17: 2003 | M17: 2000 | N17: =34*25-(I17-2000)-(J17-2000)-(K17-2000)-(L17-2000)-(M17-2000) -> 830
B18: mnqr_ceic | C18: Mining & Quarrying: SNA 2008: 2010p | D18: WIDE_CEIC | E18: IDR bn | F18: CEIC | G18: 2000 | H18: 2025 | I18: 2010 | J18: 2005 | K18: 2002 | L18: 2003 | M18: 2000 | N18: =34*25-(I18-2000)-(J18-2000)-(K18-2000)-(L18-2000)-(M18-2000) -> 830
B19: mnfr_ceic | C19: Manufacturing Industry: SNA 2008: 2010p | D19: WIDE_CEIC | E19: IDR bn | F19: CEIC | G19: 2000 | H19: 2025 | I19: 2010 | J19: 2005 | K19: 2002 | L19: 2003 | M19: 2000 | N19: =34*25-(I19-2000)-(J19-2000)-(K19-2000)-(L19-2000)-(M19-2000) -> 830
B20: expr_ceic | C20: Export of Goods and Services: SNA 2008: 2010p | D20: WIDE_CEIC | E20: IDR bn | F20: CEIC | G20: 2000 | H20: 2024 | I20: 2010 | J20: 2004 | K20: 2002 | L20: 2003 | M20: 2010 | N20: =34*25-(I20-2000)-(J20-2000)-(K20-2000)-(L20-2000)-(M20-2000) -> 821
B21: impr_ceic | C21: Import of Goods and Services: SNA 2008: 2010p | D21: WIDE_CEIC | E21: IDR bn | F21: CEIC | G21: 2000 | H21: 2024 | I21: 2010 | J21: 2004 | K21: 2002 | L21: 2003 | M21: 2010 | N21: =34*25-(I21-2000)-(J21-2000)-(K21-2000)-(L21-2000)-(M21-2000) -> 821
B22: pprj_ceic | C22: BPS' population projection | D22: WIDE_CEIC | E22: 000 people | F22: CEIC | G22: 2000 | H22: 2025 | I22: 2010 | J22: 2004 | K22: 2002 | L22: 2003 | M22: 2010
B24: Gajadi dipake
B25: Indicator | C25: Description | D25: Sheet | E25: Unit | F25: Source | G25: First Year | H25: Last Year
B26: gdpn_ceic | C26: Gross Domestic Product: SNA 2008 | D26: WIDE_IDD | E26: IDR bn | F26: CEIC | G26: 2000 | H26: 2025
B27: gdpn_idd | C27: Total GDP including Oil and Gas (in IDR Million), Current Price | D27: WIDE_IDD | E27: IDR bn | F27: INDODAPOER | G27: 2000 | H27: 2013
B28: gfcn_idd | C28: GDP expenditure on gross fixed capital formation (in IDR Million), Current Price | D28: WIDE_IDD | E28: IDR bn | F28: INDODAPOER | G28: 2000 | H28: 2013
B29: expn_idd | C29: GDP expenditure on exports (in IDR Million) | D29: WIDE_IDD | E29: IDR bn | F29: INDODAPOER | G29: 2000 | H29: 2013
B30: impn_idd | C30: GDP expenditure on imports (in IDR Million) | D30: WIDE_IDD | E30: IDR bn | F30: INDODAPOER | G30: 2000 | H30: 2013
B32: prov | C32: provname | D32: prov
B33: 11 | C33: Aceh | D33: 11
B34: 51 | C34: Bali | D34: 51
B35: 36 | C35: Banten | D35: 36
B36: 17 | C36: Bengkulu | D36: 17
B37: 34 | C37: DI Yogyakarta | D37: 34
B38: 31 | C38: DKI Jakarta | D38: 31
B39: 75 | C39: Gorontalo | D39: 75
B40: 15 | C40: Jambi | D40: 15
B41: 32 | C41: Jawa Barat | D41: 32
B42: 33 | C42: Jawa Tengah | D42: 33
B43: 35 | C43: Jawa Timur | D43: 35
B44: 61 | C44: Kalimantan Barat | D44: 61
... B66: 12 | C66: Sumatera Utara | D66: 12

Sheet FIXING IMPORT
B2: Step 2: Calculate import to GDP
B4: provname | C4: indicator | D4: 2000 | E4: 2001 | F4: 2002 | G4: 2003 | H4: 2004 | I4: 2005 | J4: 2006 | K4: 2007 | L4: 2008 | M4: 2009 | N4: 2010 | O4: 2011 | P4: 2012 | Q4: 2013 | R4: 2014 | S4: 2015 | T4: 2016 | U4: 2017 | V4: 2018 | W4: 2019 | X4: 2020 | Y4: 2021 | Z4: 2022 | AA4: 2023 | AB4: 2024
B5: Aceh | C5: share | D5: =D78/D41 -> 0.42761293 | E5: =E78/E41 -> 0.48745762 | F5: =F78/F41 -> 0.077022653 | G5: =G78/G41 -> 0.13900632 | H5: =H78/H41 -> 0.098896087 | I5: =I78/I41 -> 0.8649862 | J5: =J78/J41 -> 0.06776372 | K5: =K78/K41 -> 0.42491019 | ... AB5: =AB78/AB41 -> 0.5804791
B6: Bali | C6: share | D6: =D79/D42 -> 0.050130701 | E6: =E79/E42 -> 0.048516289 | F6: =F79/F42 -> 0.048733343 | G6: =G79/G42 -> 0.049377864 | H6: =H79/H42 -> 0.084227239 | I6: =I79/I42 -> 0.092482286 | J6: =J79/J42 -> 0.078732321 | K6: =K79/K42 -> 0.093030644 | ... AB6: =AB79/AB42 -> 0.054160948
B7: Banten | C7: share | D7: =D80/D43 -> 0.72469539 | E7: =E80/E43 -> 0.67793069 | F7: =F80/F43 -> 0.72291111 | G7: =G80/G43 -> 0.7626953 | H7: =H80/H43 -> 0.80923964 | I7: =I80/I43 -> 0.83711333 | J7: =J80/J43 -> 0.88312921 | K7: =K80/K43 -> 0.89643627 | ... AB7: =AB80/AB43 -> 0.69557636
B8: Bengkulu | C8: share | D8: =D81/D44 -> 0.60686146 | E8: =E81/E44 -> 0.57884255 | F8: =F81/F44 -> 0.56673304 | G8: =G81/G44 -> 0.55139536 | H8: =H81/H44 -> 0.5830919 | I8: =I81/I44 -> 0.62613437 | J8: =J81/J44 -> 0.6222205 | K8: =K81/K44 -> 0.64407054 | ... AB8: =AB81/AB44 -> 0.62581161
B9: DI Yogyakarta | C9: share | D9: =D82/D45 -> 0.02140998 | E9: =E82/E45 -> 0.022312139 | F9: =F82/F45 -> 0.022645959 | G9: =G82/G45 -> 0.023444959 | H9: =H82/H45 -> 0.02338288 | I9: =I82/I45 -> 0.023302368 | J9: =J82/J45 -> 0.023433683 | K9: =K82/K45 -> 0.023602627 | ... AB9: =AB82/AB45 -> 0.036137638
B10: DKI Jakarta | C10: share | D10: =D83/D46 -> 0.51373676 | E10: =E83/E46 -> 0.38648251 | F10: =F83/F46 -> 0.36178596 | G10: =G83/G46 -> 0.41841376 | H10: =H83/H46 -> 0.49104245 | I10: =I83/I46 -> 0.54670984 | J10: =J83/J46 -> 0.54412099 | K10: =K83/K46 -> 0.57457246 | ... AB10: =AB83/AB46 -> 0.70875011
B11: Gorontalo | C11: share | D11: =D84/D47 -> 0.018836278 | E11: =E84/E47 -> 0.023150469 | F11: =F84/F47 -> 0.022464791 | G11: =G84/G47 -> 0.17585265 | H11: =H84/H47 -> 0.20176377 | I11: =I84/I47 -> 0.1145323 | J11: =J84/J47 -> 0.27375993 | K11: =K84/K47 -> 0.32373191 | ... AB11: =AB84/AB47 -> 0.34100451
B12: Jambi | C12: share | D12: =D85/D48 -> 0.35830935 | E12: =E85/E48 -> 0.38051619 | F12: =F85/F48 -> 0.36084876 | G12: =G85/G48 -> 0.38154804 | H12: =H85/H48 -> 0.39628764 | I12: =I85/I48 -> 0.44371658 | J12: =J85/J48 -> 0.47657423 | K12: =K85/K48 -> 0.52964101 | ... AB12: =AB85/AB48 -> 0.38840717
B13: Jawa Barat | C13: share | D13: =D86/D49 -> 0.3529103 | E13: =E86/E49 -> 0.44228306 | F13: =F86/F49 -> 0.62600645 | G13: =G86/G49 -> 0.62280743 | H13: =H86/H49 -> 0.67789956 | I13: =I86/I49 -> 0.65488218 | J13: =J86/J49 -> 0.55154179 | K13: =K86/K49 -> 0.47998071 | ... AB13: =AB86/AB49 -> 0.42999002
B14: Jawa Tengah | C14: share | D14: =D87/D50 -> 0.21649265 | E14: =E87/E50 -> 0.18680279 | F14: =F87/F50 -> 0.1728149 | G14: =G87/G50 -> 0.18270503 | H14: =H87/H50 -> 0.18232158 | I14: =I87/I50 -> 0.18990523 | J14: =J87/J50 -> 0.17428284 | K14: =K87/K50 -> 0.16725214 | ... AB14: =AB87/AB50 -> 0.15719542
B15: Jawa Timur | C15: share | D15: =D88/D51 -> 0.40325862 | E15: =E88/E51 -> 0.38049599 | F15: =F88/F51 -> 0.34706734 | G15: =G88/G51 -> 0.33749974 | H15: =H88/H51 -> 0.34597638 | I15: =I88/I51 -> 0.37283348 | J15: =J88/J51 -> 0.37435515 | K15: =K88/K51 -> 0.37084858 | ... AB15: =AB88/AB51 -> 0.48602219
B16: Kalimantan Barat | C16: share | D16: =D89/D52 -> 0.20516969 | E16: =E89/E52 -> 0.18525409 | F16: =F89/F52 -> 0.15910445 | G16: =G89/G52 -> 0.1689621 | H16: =H89/H52 -> 0.15977412 | I16: =I89/I52 -> 0.15661973 | J16: =J89/J52 -> 0.17607001 | K16: =K89/K52 -> 0.14580523 | ... AB16: =AB89/AB52 -> 0.14344349
... B19: Kalimantan Timur | C19: share | D19: =D92/D55 -> 0.38582013 | E19: =E92/E55 -> 0.4031418 | F19: =F92/F55 -> 0.39162042 | G19: =G92/G55 -> 0.42167338 | H19: =H92/H55 -> 0.46741642 | I19: =I92/I55 -> 0.53143522 | J19: =J92/J55 -> 0.57013057 | K19: =K92/K55 -> 0.58231853 | ... AB19: =AB92/AB55 -> 0.59686989
B20: Kalimantan Utara | C20: share | N20: =N93/N56 -> 0.45279992 | O20: =O93/O56 -> 0.44453237 | P20: =P93/P56 -> 0.448904 | Q20: =Q93/Q56 -> 0.448606 | R20: =R93/R56 -> 0.4529406 | S20: =S93/S56 -> 0.44359872 | T20: =T93/T56 -> 0.44575422 | U20: =U93/U56 -> 0.43518154 | ... AB20: =AB93/AB56 -> 0.55716261
B21: Kep. Bangka Belitung | C21: share | D21: =D94/D57 -> 0.24576445 | E21: =E94/E57 -> 0.28153057 | F21: =F94/F57 -> 0.24136502 | G21: =G94/G57 -> 0.23802515 | H21: =H94/H57 -> 0.50005072 | I21: =I94/I57 -> 0.5578309 | J21: =J94/J57 -> 0.55675633 | K21: =K94/K57 -> 0.5281956 | ... AB21: =AB94/AB57 -> 0.24169882
B22: Kep. Riau | C22: share | G22: =G95/G58 -> 0.64534568 | H22: =H95/H58 -> 0.89525311 | I22: =I95/I58 -> 1.044989 | J22: =J95/J58 -> 0.99891127 | K22: =K95/K58 -> 1.0881082 | L22: =L95/L58 -> 1.2032722 | M22: =M95/M58 -> 1.2516054 | N22: =N95/N58 -> 1.3278403 | ... AB22: =AB95/AB58 -> 1.418459
B23: Lampung | C23: share | D23: =D96/D59 -> 0.42927958 | E23: =E96/E59 -> 0.40022736 | F23: =F96/F59 -> 0.4304018 | G23: =G96/G59 -> 0.43129792 | H23: =H96/H59 -> 0.32348493 | I23: =I96/I59 -> 0.34186891 | J23: =J96/J59 -> 0.34813772 | K23: =K96/K59 -> 0.33995117 | ... AB23: =AB96/AB59 -> 0.53193431
B24: Maluku | C24: share | D24: =D97/D60 -> 0.44976657 | E24: =E97/E60 -> 0.61154851 | F24: =F97/F60 -> 0.61771438 | G24: =G97/G60 -> 0.59696848 | H24: =H97/H60 -> 0.56576607 | I24: =I97/I60 -> 0.54641945 | J24: =J97/J60 -> 0.56957142 | K24: =K97/K60 -> 0.57745868 | ... AB24: =AB97/AB60 -> 0.15723409
B25: Maluku Utara | C25: share | D25: =D98/D61 -> 0.5084237 | E25: =E98/E61 -> 0.38778618 | F25: =F98/F61 -> 0.41613068 | G25: =G98/G61 -> 0.38325338 | H25: =H98/H61 -> 0.43719309 | I25: =I98/I61 -> 0.44797299 | J25: =J98/J61 -> 0.46643479 | K25: =K98/K61 -> 0.36887581 | ... AB25: =AB98/AB61 -> 2.5370906
B26: Nusa Tenggara Barat | C26: share | D26: =D99/D62 -> 0.54487114 | E26: =E99/E62 -> 0.51174561 | F26: =F99/F62 -> 0.50970572 | G26: =G99/G62 -> 0.49488789 | H26: =H99/H62 -> 0.51041466 | I26: =I99/I62 -> 0.56322056 | J26: =J99/J62 -> 0.57686099 | K26: =K99/K62 -> 0.57796961 | ... AB26: =AB99/AB62 -> 0.41265728
B27: Nusa Tenggara Timur | C27: share | D27: =D100/D63 -> 0.3084738 | E27: =E100/E63 -> 0.34898538 | F27: =F100/F63 -> 0.36683717 | G27: =G100/G63 -> 0.35037946 | H27: =H100/H63 -> 0.39949558 | I27: =I100/I63 -> 0.44576877 | J27: =J100/J63 -> 0.47438564 | K27: =K100/K63 -> 0.49695799 | ... AB27: =AB100/AB63 -> 0.50416648
B28: Papua | C28: share | D28: =D101/D64 -> 0.056655697 | E28: =E101/E64 -> 0.04895975 | F28: =F101/F64 -> 0.049427395 | G28: =G101/G64 -> 0.053661004 | H28: =H101/H64 -> 0.070087134 | I28: =I101/I64 -> 0.058054736 | J28: =J101/J64 -> 0.085868166 | K28: =K101/K64 -> 0.076646993 | ... AB28: =AB101/AB64 -> 0.42008968
B29: Papua Barat | C29: share | F29: =F102/F65 -> 0.98041493 | G29: =G102/G65 -> 0.84208442 | H29: =H102/H65 -> 0.74016999 | I29: =I102/I65 -> 0.83230986 | J29: =J102/J65 -> 0.93844174 | K29: =K102/K65 -> 0.89035395 | L29: =L102/L65 -> 0.79236112 | M29: =M102/M65 -> 0.5306499 | ... AB29: =AB102/AB65 -> 0.2688619
B30: Riau | C30: share | D30: =D103/D66 -> 0.14390886 | E30: =E103/E66 -> 0.13670843 | F30: =F103/F66 -> 0.13215371 | G30: =G103/G66 -> 0.13731425 | H30: =H103/H66 -> 0.14281107 | I30: =I103/I66 -> 0.15314207 | J30: =J103/J66 -> 0.16066511 | K30: =K103/K66 -> 0.1702624 | ... AB30: =AB103/AB66 -> 0.32048683
B31: Sulawesi Barat | C31: share | I31: =I104/I67 -> 0.4476623 | J31: =J104/J67 -> 0.49524264 | K31: =K104/K67 -> 0.55933451 | L31: =L104/L67 -> 0.61170597 | M31: =M104/M67 -> 0.63233642 | N31: =N104/N67 -> 0.63210353 | O31: =O104/O67 -> 0.63772883 | P31: =P104/P67 -> 0.61431834 | ... AB31: =AB104/AB67 -> 0.35006489
B32: Sulawesi Selatan | C32: share | D32: =D105/D68 -> 0.18023939 | E32: =E105/E68 -> 0.25203213 | F32: =F105/F68 -> 0.18412143 | G32: =G105/G68 -> 0.17318501 | H32: =H105/H68 -> 0.28294491 | I32: =I105/I68 -> 0.34333542 | J32: =J105/J68 -> 0.32037806 | K32: =K105/K68 -> 0.40828799 | ... AB32: =AB105/AB68 -> 0.11527465
B33: Sulawesi Tengah | C33: share | D33: =D106/D69 -> 0.37843301 | E33: =E106/E69 -> 0.36853842 | F33: =F106/F69 -> 0.36035932 | G33: =G106/G69 -> 0.34486699 | H33: =H106/H69 -> 0.33111118 | I33: =I106/I69 -> 0.31823594 | J33: =J106/J69 -> 0.30980837 | K33: =K106/K69 -> 0.48969235 | ... AB33: =AB106/AB69 -> 1.0734582
B34: Sulawesi Tenggara | C34: share | D34: =D107/D70 -> 0.18036802 | E34: =E107/E70 -> 0.18882004 | F34: =F107/F70 -> 0.18730713 | G34: =G107/G70 -> 0.19355181 | H34: =H107/H70 -> 0.24639377 | I34: =I107/I70 -> 0.27089933 | J34: =J107/J70 -> 0.35584094 | K34: =K107/K70 -> 0.34859304 | ... AB34: =AB107/AB70 -> 0.46528073
B35: Sulawesi Utara | C35: share | D35: =D108/D71 -> 0.22204444 | E35: =E108/E71 -> 0.12259482 | F35: =F108/F71 -> 0.12406007 | G35: =G108/G71 -> 0.1625203 | H35: =H108/H71 -> 0.26211821 | I35: =I108/I71 -> 0.29069943 | J35: =J108/J71 -> 0.26755748 | K35: =K108/K71 -> 0.27122233 | ... AB35: =AB108/AB71 -> 0.21873911
B36: Sumatera Barat | C36: share | D36: =D109/D72 -> 0.34119292 | E36: =E109/E72 -> 0.28434227 | F36: =F109/F72 -> 0.26686018 | G36: =G109/G72 -> 0.3213419 | H36: =H109/H72 -> 0.3057362 | I36: =I109/I72 -> 0.39826231 | J36: =J109/J72 -> 0.40938767 | K36: =K109/K72 -> 0.52853235 | ... AB36: =AB109/AB72 -> 0.48536262
B37: Sumatera Selatan | C37: share | D37: =D110/D73 -> 0.33243838 | E37: =E110/E73 -> 0.32887945 | F37: =F110/F73 -> 0.33718245 | G37: =G110/G73 -> 0.30035556 | H37: =H110/H73 -> 0.31676061 | I37: =I110/I73 -> 0.32635569 | J37: =J110/J73 -> 0.32389747 | K37: =K110/K73 -> 0.3402954 | ... AB37: =AB110/AB73 -> 0.29896317
B38: Sumatera Utara | C38: share | D38: =D111/D74 -> 0.23037669 | E38: =E111/E74 -> 0.23213838 | F38: =F111/F74 -> 0.23206863 | G38: =G111/G74 -> 0.21530603 | H38: =H111/H74 -> 0.2497986 | I38: =I111/I74 -> 0.27170521 | J38: =J111/J74 -> 0.28311359 | K38: =K111/K74 -> 0.31906705 | ... AB38: =AB111/AB74 -> 0.32494246
B40: provname | C40: indicator | D40: 2000 | E40: 2001 | F40: 2002 | G40: 2003 | H40: 2004 | I40: 2005 | J40: 2006 | K40: 2007 | L40: 2008 | M40: 2009 | N40: 2010 | O40: 2011 | P40: 2012 | Q40: 2013 | R40: 2014 | S40: 2015 | T40: 2016 | U40: 2017 | V40: 2018 | W40: 2019 | X40: 2020 | Y40: 2021 | Z40: 2022 | AA40: 2023 | AB40: 2024
B41: Aceh | C41: rdgp_ceic | D41: 110073.1 | E41: 108170.82 | F41: 129876.08 | G41: 137049.26 | H41: 123849.98 | I41: 111314.86 | J41: 113050.95 | K41: 110379.79 | L41: 104597.17 | M41: 98833.537 | N41: 101545.24 | O41: 104874.21 | P41: 108914.9 | Q41: 111755.83 | R41: 113490.36 | S41: 112665.53 | T41: 116374.3 | U41: 121240.98 | V41: 126824.37 | W41: 132069.62 | X41: 131580.97 | Y41: 135274.04 | Z41: 140971.72 | AA41: 146932.5 | AB41: 153780.49
B42: Bali | C42: rdgp_ceic | D42: 56050.74 | E42: 58036.078 | F42: 59801.795 | G42: 61934.458 | H42: 64798.46 | I42: 68398.803 | J42: 72008.991 | K42: 79361.599 | L42: 84102.023 | M42: 88583.362 | N42: 93749.35 | O42: 99991.632 | P42: 106951.46 | Q42: 114103.58 | R42: 121787.57 | S42: 129126.56 | T42: 137296.45 | U42: 144933.31 | V42: 154072.66 | W42: 162693.36 | X42: 147498.94 | Y42: 143871.68 | Z42: 150830.77 | AA42: 159464.3 | AB42: 168198.68
B43: Banten | C43: rdgp_ceic | D43: 138907.81 | E43: 145601.68 | F43: 151591.67 | G43: 159280.6 | H43: 168241.18 | I43: 178132.46 | J43: 188048.78 | K43: 230991.51 | L43: 244330.14 | M43: 255835.47 | N43: 271465.28 | O43: 290545.84 | P43: 310385.59 | Q43: 331099.11 | R43: 349351.23 | S43: 368377.2 | T43: 387835.09 | U43: 410137 | V43: 433782.71 | W43: 456620.03 | X43: 441148.58 | Y43: 460952.79 | Z43: 484129.42 | AA43: 507425.73 | AB43: 531735.25
B44: Bengkulu | C44: rdgp_ceic | D44: 16550.039 | E44: 17236.785 | F44: 18052.424 | G44: 19021.376 | H44: 20045.454 | I44: 21211.919 | J44: 22474.093 | K44: 23925.008 | L44: 25300.078 | M44: 26721.308 | N44: 28352.572 | O44: 30295.054 | P44: 32363.038 | Q44: 34326.372 | R44: 36207.146 | S44: 38066.006 | T44: 40076.544 | U44: 42073.516 | V44: 44164.11 | W44: 46345.454 | X44: 46338.431 | Y44: 47853.777 | Z44: 49916.061 | AA44: 52051.6 | AB44: 54454.65
B45: DI Yogyakarta | C45: rdgp_ceic | D45: 41432.689 | E45: 43198.331 | F45: 45141.443 | G45: 47210.294 | H45: 49626.114 | I45: 52064.2 | J45: 53894.999 | K45: 56219.054 | L45: 59049.658 | M45: 61667.594 | N45: 64678.968 | O45: 68049.874 | P45: 71702.449 | Q45: 75627.45 | R45: 79536.082 | S45: 83474.452 | T45: 87685.81 | U45: 92300.244 | V45: 98024.014 | W45: 104485.46 | X45: 101698.52 | Y45: 107372.56 | Z45: 112901.32 | AA45: 118625.55 | AB45: 124590.45
...

Sheet RAW_CEIC
A1: indicator | B1: provname_en | C1: provname_pap | D1: provname | E1: 2000 | F1: 2001 | G1: 2002 | H1: 2003 | I1: 2004 | J1: 2005 | K1: 2006 | L1: 2007 | M1: 2008 | N1: 2009 | O1: 2010 | P1: 2011 | Q1: 2012 | R1: 2013 | S1: 2014 | T1: 2015 | U1: 2016 | V1: 2017 | W1: 2018 | X1: 2019 | Y1: 2020 | Z1: 2021 | AA1: 2022 | AB1: 2023 | AC1: 2024 | AD1: 2025
A2: agrr_ceic | B2: Aceh | C2: Aceh | D2: Aceh | E2: 21575.61 | F2: 20882.8 | G2: 21327.97 | H2: 22025.17 | I2: 23356.22 | J2: 22447.34 | K2: 22788.31 | L2: 23612.76 | M2: 23803.54 | N2: 24412.68 | O2: 25579.57 | P2: 26515.48 | Q2: 27685.11 | R2: 28980.43 | S2: 29690.56 | T2: 31186.38 | U2: 32355.09 | V2: 34052.85 | W2: 35426.16 | X2: 36626.71 | Y2: 37899.52 | Z2: 37768.08 | AA2: 39005.09 | AB2: 41626.32 | AC2: 42121.38 | AD2: 43637.59
A3: agrr_ceic | B3: Bali | C3: Bali | D3: Bali | E3: 10487.44 | F3: 11082.48 | G3: 11488.73 | H3: 11905.69 | I3: 12341.19 | J3: 12858.93 | K3: 13386.6 | L3: 14618.96 | M3: 14963.8 | N3: 15813.19 | O3: 16092.72 | P3: 16258.74 | Q3: 16969.88 | R3: 17343.29 | S3: 18151.21 | T3: 18637.35 | U3: 19295.7 | V3: 19821.71 | W3: 20760.22 | X3: 21479.55 | Y3: 21269.19 | Z3: 21338.45 | AA3: 21157.3 | AB3: 21058.7 | AC3: 21586.55 | AD3: 21954.29
A4: agrr_ceic | B4: Bangka Belitung | C4: Kep. Bangka Belitung | D4: Kep. Bangka Belitung | E4: 3798.22 | F4: 4111.44 | G4: 4317.44 | H4: 4410.78 | I4: 4606.99 | J4: 4824.45 | K4: 5090.6 | L4: 5244.62 | M4: 5457.99 | N4: 5658.28 | O4: 6097.69 | P4: 6642.8 | Q4: 7072.89 | R4: 7557.66 | S4: 8254.34 | T4: 8743.51 | U4: 9123.19 | V4: 9095.69 | W4: 9589.72 | X4: 9862.83 | Y4: 10666.36 | Z4: 10768.72 | AA4: 10875.68 | AB4: 11281.88 | AC4: 11634.94 | AD4: 12003.87
A5: agrr_ceic | B5: Banten | C5: Banten | D5: Banten | E5: 10985.99 | F5: 11506.54 | G5: 11692.12 | H5: 12037.69 | I5: 12287.14 | J5: 12614.58 | K5: 12535.72 | L5: 14118.95 | M5: 14569.42 | N5: 15354.49 | O5: 16737.61 | P5: 17242.08 | Q5: 17793.38 | R5: 18990.92 | S5: 19456.95 | T5: 20743.47 | U5: 22108.75 | V5: 23055.55 | W5: 23880.77 | X5: 24408.33 | Y5: 25275.08 | Z5: 25416.58 | AA5: 26490.53 | AB5: 26531.3 | AC5: 26703.35 | AD5: 29266.23
A6: agrr_ceic | B6: Bengkulu | C6: Bengkulu | D6: Bengkulu | E6: 5728.65 | F6: 5937.16 | G6: 6202.04 | H6: 6565.87 | I6: 6928.19 | J6: 7331.42 | K6: 7751.37 | L6: 8189.66 | M6: 8643.42 | N6: 9119.25 | O6: 9343.96 | P6: 9734.67 | Q6: 10272.89 | R6: 10687.21 | S6: 10950.44 | T6: 11197.98 | U6: 11551.54 | V6: 11929.47 | W6: 12309.49 | X6: 12747.26 | Y6: 12795.99 | Z6: 13109.72 | AA6: 13699.33 | AB6: 13981.69 | AC6: 14341.27 | AD6: 14930.39
A7: agrr_ceic | B7: Central Java | C7: Jawa Tengah | D7: Jawa Tengah | E7: 74414.1 | F7: 75249.33 | G7: 78974.16 | H7: 77357.68 | I7: 81484.1 | J7: 85239.54 | K7: 88308.93 | L7: 90760.04 | M7: 93659.82 | N7: 97136.21 | O7: 99572.44 | P7: 103389.33 | Q7: 106536.7 | R7: 108832.11 | S7: 107793.38 | T7: 113826.3 | U7: 116331.12 | V7: 118450.17 | W7: 121554.48 | X7: 123150.02 | Y7: 126111.76 | Z7: 127065.84 | AA7: 130762.52 | AB7: 131330.54 | AC7: 133162.54 | AD7: 139530.4
A8: agrr_ceic | B8: Central Kalimantan | C8: Kalimantan Tengah | D8: Kalimantan Tengah | E8: 11342.89 | F8: 11846.56 | G8: 11594.9 | H8: 12535.97 | I8: 12561.59 | J8: 12695.63 | K8: 13122.8 | L8: 13175.81 | M8: 13118.8 | N8: 13541.43 | O8: 13935.36 | P8: 14165.41 | Q8: 14536.58 | R8: 15028.38 | S8: 16080.17 | T8: 17031.88 | U8: 17686.42 | V8: 18514.01 | W8: 19824.58 | X8: 21250.83 | Y8: 21304.92 | Z8: 22073.16 | AA8: 22834.25 | AB8: 23830.77 | AC8: 24138.62 | AD8: 25090.12
A9: agrr_ceic | B9: Central Papua | C9: Papua Tengah | D9: Papua | AA9: 3769.69 | AB9: 3829.34 | AC9: 3865.81 | AD9: 3966.19
A10: agrr_ceic | B10: Central Sulawesi | C10: Sulawesi Tengah | D10: Sulawesi Tengah | E10: 10450.93 | F10: 11123.93 | G10: 11885.49 | H10: 12772.13 | I10: 13766.84 | J10: 14650.9 | K10: 15448.99 | L10: 16550.24 | M10: 17312.7 | N10: 18419.21 | O10: 19523.49 | P10: 20711.36 | Q10: 21923.49 | R10: 23163.93 | S10: 24728.72 | T10: 26297.82 | U10: 26929.49 | V10: 28131.33 | W10: 29340.85 | X10: 29995.99 | Y10: 29593.65 | Z10: 30793.12 | AA10: 31639.57 | AB10: 32224.74 | AC10: 32848.02 | AD10: 34309.75
A11: agrr_ceic | B11: DI Yogyakarta | C11: DI Yogyakarta | D11: DI Yogyakarta | E11: 5533.2 | F11: 5759.8 | G11: 5860.64 | H11: 5886.44 | I11: 6095.14 | J11: 6360.34 | K11: 6602.23 | L11: 6655.05 | M11: 7035.5 | N11: 7272.59 | O11: 7252.6 | P11: 7134.68 | Q11: 7500.73 | R11: 7670.03 | S11: 7508.98 | T11: 7667.6 | U11: 7779.8 | V11: 7930.31 | W11: 8101.23 | X11: 8184.19 | Y11: 8534.64 | Z11: 8638.19 | AA11: 9077.78 | AB11: 9194.03 | AC11: 9206.5 | AD11: 9791.84
A12: agrr_ceic | B12: DKI Jakarta | C12: DKI Jakarta | D12: DKI Jakarta | E12: 1640.57 | F12: 1594.77 | G12: 1448.79 | H12: 1221.17 | I12: 1205.61 | J12: 1218.29 | K12: 1232.01 | L12: 1251.06 | M12: 1260.72 | N12: 1265.06 | O12: 1275.63 | P12: 1277.28 | Q12: 1319.31 | R12: 1353.56 | S12: 1359.95 | T12: 1375.42 | U12: 1387.53 | V12: 1391.53 | W12: 1394.05 | X12: 1398.22 | Y12: 1405.1 | Z12: 1463.34 | AA12: 1501.26 | AB12: 1443.04 | AC12: 1516.95 | AD12: 1561.67
A13: agrr_ceic | B13: East Java | C13: Jawa Timur | D13: Jawa Timur | E13: 104112.98 | F13: 105425.77 | G13: 107560.12 | H13: 109612.12 | I13: 112702.18 | J13: 116264.13 | K13: 118147.24 | L13: 121859.06 | M13: 125664.22 | N13: 130589.82 | O13: 133504.56 | P13: 138870.09 | Q13: 146002.57 | R13: 150463.72 | S13: 155783.96 | T13: 160889.4 | U13: 164762.91 | V13: 167360.57 | W13: 163799.94 | X13: 165951.23 | Y13: 167631.24 | Z13: 170556.77 | AA13: 173747.56 | AB13: 177668.37 | AC13: 177809.47 | AD13: 186662.71
A14: agrr_ceic | B14: East Kalimantan | C14: Kalimantan Timur | D14: Kalimantan Timur | E14: 16282.68 | F14: 16580.67 | G14: 17030 | H14: 17214.66 | I14: 17708.7 | J14: 18161.03 | K14: 18806.2 | L14: 19141.98 | M14: 19698.74 | N14: 19993.01 | O14: 21167.77 | P14: 22292.61 | Q14: 23991.79 | R14: 25535.67 | S14: 27267.2 | T14: 28506.91 | U14: 28639.4 | V14: 30261.4 | W14: 32140.16 | X14: 33355.19 | Y14: 33026.69 | Z14: 33003.9 | AA14: 33712.58 | AB14: 34551.18 | AC14: 35368.75 | AD14: 38094.43
A15: agrr_ceic | B15: East Nusa Tenggara | C15: Nusa Tenggara Timur | D15: Nusa Tenggara Timur | E15: 10469.09 | F15: 10799.67 | G15: 11205.53 | H15: 11435.39 | I15: 11835.1 | J15: 11949.36 | K15: 12540.98 | L15: 12884.94 | M15: 13379.21 | N15: 13684.3 | O15: 13963.14 | P15: 14244.98 | Q15: 14669.95 | R15: 15069.63 | S15: 15613.95 | T15: 16123.17 | U15: 16512.69 | V15: 17328.87 | W15: 17837.81 | X15: 18496.01 | Y15: 18680.64 | Z15: 19601.9 | AA15: 20341.73 | AB15: 20842.3 | AC15: 21224.74 | AD15: 21967.56
A16: agrr_ceic | B16: Gorontalo | C16: Gorontalo | D16: Gorontalo | E16: 3287.79 | F16: 3519.47 | G16: 3826.86 | H16: 3998.73 | I16: 4125.14 | J16: 4432.57 | K16: 4784.47 | L16: 5134.78 | M16: 5548.66 | N16: 5742.5 | O16: 5977.73 | P16: 6321.23 | Q16: 6763.85 | R16: 7232.59 | S16: 7698.32 | T16: 8024.61 | U16: 8540.36 | V16: 9314.37 | W16: 10019.05 | X16: 10652.83 | Y16: 10478.78 | Z16: 10663.64 | AA16: 10907.95 | AB16: 11365.5 | AC16: 11719.48 | AD16: 12205.24
A17: agrr_ceic | B17: Jambi | C17: Jambi | D17: Jambi | E17: 13821.41 | F17: 14334.5 | G17: 15029.5 | H17: 15563.87 | I17: 16354.9 | J17: 17108.3 | K17: 19047.67 | L17: 19917.72 | M17: 21056.68 | N17: 22458.21 | O17: 23627.24 | P17: 24744.88 | Q17: 26429.05 | R17: 28070.96 | S17: 31145.43 | T17: 32846.19 | U17: 34933.69 | V17: 36809.09 | W17: 38041.61 | X17: 39160.08 | Y17: 39751.94 | Z17: 41209.13 | AA17: 43268.38 | AB17: 45698.37 | AC17: 47643.01 | AD17: 50259.68
A18: agrr_ceic | B18: Lampung | C18: Lampung | D18: Lampung | E18: 36401.86 | F18: 37589.5 | G18: 38093.11 | H18: 39660.9 | I18: 41879.08 | J18: 43834.02 | K18: 46198.15 | L18: 48747.48 | M18: 50168.11 | N18: 51486.83 | O18: 52038.77 | P18: 54841.03 | Q18: 56997.47 | R18: 59636.49 | S18: 61595.15 | T18: 63745.49 | U18: 65730.54 | V18: 66297.14 | W18: 66941.02 | X18: 67848.65 | Y18: 68312.25 | Z18: 67969.86 | AA18: 69317.66 | AB18: 69697.99 | AC18: 68339.77 | AD18: 72381.45
A19: agrr_ceic | B19: Maluku | C19: Maluku | D19: Maluku | E19: 3670.3 | F19: 3627.36 | G19: 3663.05 | H19: 3734.53 | I19: 3839.09 | J19: 3978.62 | K19: 4096.73 | L19: 4265.79 | M19: 4388.96 | N19: 4567.08 | O19: 4825.72 | P19: 4972.6 | Q19: 5282.61 | R19: 5500.92 | S19: 5835.44 | T19: 5908.36 | U19: 6188.01 | V19: 6558.6 | W19: 6858.55 | X19: 7230.24 | Y19: 7353.71 | Z19: 7409.16 | AA19: 7833.24 | AB19: 8276.73 | AC19: 8557.59 | AD19: 9106.61
A20: agrr_ceic | B20: North Kalimantan | C20: Kalimantan Utara | D20: Kalimantan Utara | O20: 6235.36 | P20: 6676.56 | Q20: 7130 | R20: 7496.93 | S20: 8021.34 | T20: 8574.02 | U20: 9022 | V20: 9423 | W20: 9941.19 | X20: 10475.64 | Y20: 10925.64 | Z20: 11300.51 | AA20: 11723.08 | AB20: 12229.92 | AC20: 12444.24 | AD20: 12767.3
A21: agrr_ceic | B21: North Maluku | C21: Maluku Utara | D21: Maluku Utara | E21: 2514.56 | F21: 2562.49 | G21: 2645.37 | H21: 2768.44 | I21: 2848.76 | J21: 2974.86 | K21: 3116.28 | L21: 4102.26 | M21: 3936.69 | N21: 3739.01 | O21: 3936.69 | P21: 4105.56 | Q21: 4371.36 | R21: 4525.96 | S21: 4662.5 | T21: 4742.55 | U21: 4943.91 | V21: 5100.39 | W21: 5305.88 | X21: 5518.06 | Y21: 5594.84 | Z21: 5727.23 | AA21: 5911.57 | AB21: 6162.71 | AC21: 6440.92 | AD21: 6646.89
A22: agrr_ceic | B22: North Sulawesi | C22: Sulawesi Utara | D22: Sulawesi Utara | E22: 7667.12 | F22: 7964.89 | G22: 8320.34 | H22: 8392.96 | I22: 8947.76 | J22: 9497.69 | K22: 9740.67 | L22: 10479.52 | M22: 11089.02 | N22: 11318.59 | O22: 12281.01 | P22: 12154.19 | Q22: 12918.08 | R22: 13765.3 | S22: 14243.12 | T22: 14605.52 | U22: 15141.89 | V22: 15814.32 | W22: 16367.26 | X22: 17320.48 | Y22: 17705.45 | Z22: 18040.14 | AA22: 19187.16 | AB22: 20036.33 | AC22: 21113.98 | AD22: 22337.2
A23: agrr_ceic | B23: North Sumatera | C23: Sumatera Utara | D23: Sumatera Utara | E23: 57864.17 | F23: 60061.78 | G23: 61584.13 | H23: 63131.37 | I23: 65499.04 | J23: 67713.98 | K23: 69340.93 | L23: 72794.06 | M23: 77201.71 | N23: 80943.58 | O23: 85561.14 | P23: 90592.55 | Q23: 95405.42 | R23: 99894.57 | S23: 104262.83 | T23: 110066 | U23: 115179.69 | V23: 121300.04 | W23: 127202.65 | X23: 133726.02 | Y23: 136327.03 | Z23: 141601.18 | AA23: 148721.97 | AB23: 153246.71 | AC23: 158940.62 | AD23: 166702.96
A24: agrr_ceic | B24: Papua | C24: Papua | D24: Papua | E24: 11391.95 | F24: 12512.43 | G24: 8854.27 | H24: 9280.62 | I24: 9223.47 | J24: 9668.39 | K24: 10171.16 | L24: 10309.74 | M24: 10793.27 | N24: 11248.9 | O24: 11681.13 | P24: 12133.26 | Q24: 12883.7 | R24: 13661.8 | S24: 14432.99 | T24: 15192.6 | U24: 15461.69 | V24: 16070.49 | W24: 16602.56 | X24: 16608.11 | Y24: 16490.61 | Z24: 16755.83 | AA24: 17135.86 | AB24: 7017.85 | AC24: 7073.68 | AD24: 7401.07
A25: agrr_ceic | B25: Papua Mountains | C25: Papua Pegunungan | D25: Papua | AA25: 2276.97 | AB25: 2333.87 | AC25: 2409.55 | AD25: 2483.29
A26: agrr_ceic | B26: Riau | C26: Riau | D26: Riau | E26: 59133.63 | F26: 62824.44 | G26: 66608.53 | H26: 63611.7 | I26: 68065.58 | J26: 72673.07 | K26: 77010.89 | L26: 80739.72 | M26: 84607.9 | N26: 87757.75 | O26: 91152.77 | P26: 94307.4 | Q26: 97910.95 | R26: 102216.74 | S26: 108498.09 | T26: 108969.04 | U26: 113287.59 | V26: 119281.64 | W26: 124547.86 | X26: 129690.41 | Y26: 135124.21 | Z26: 140717.74 | AA26: 144691.04 | AB26: 149361.11 | AC26: 152698.4 | AD26: 160178.56
A27: agrr_ceic | B27: Riau Islands | C27: Kep. Riau | D27: Kep. Riau | H27: 3288.86 | I27: 3476.17 | J27: 3663.79 | K27: 3862.14 | L27: 4105.26 | M27: 4261.11 | N27: 4324.91 | O27: 4506.56 | P27: 4683.47 | Q27: 4794.17 | R27: 5000.01 | S27: 5378.15 | T27: 5689.22 | U27: 6018.41 | V27: 5945.61 | W27: 5757.78 | X27: 5717.73 | Y27: 5466.78 | Z27: 5322.05 | AA27: 5601.86 | AB27: 5687.64 | AC27: 5720.17 | AD27: 5919.88
A28: agrr_ceic | B28: South East Sulawesi | C28: Sulawesi Tenggara | D28: Sulawesi Tenggara | E28: 8231.62 | F28: 8673.44 | G28: 9302.72 | H28: 9875.04 | I28: 10649.04 | J28: 11385.14 | K28: 11905.93 | L28: 12572.51 | M28: 13205.9 | N28: 13566.97 | O28: 13741.14 | P28: 14007.46 | Q28: 14625.41 | R28: 15508.22 | S28: 16952.31 | T28: 16970.46 | U28: 18270.18 | V28: 19323.26 | W28: 20554.63 | X28: 21581.03 | Y28: 21728.37 | Z28: 22247.11 | AA28: 23754.98 | AB28: 24779.74 | AC28: 25734.91 | AD28: 26698.67
A29: agrr_ceic | B29: South Kalimantan | C29: Kalimantan Selatan | D29: Kalimantan Selatan | E29: 8386.9 | F29: 9058.77 | G29: 9309.45 | H29: 9585.57 | I29: 10161.95 | J29: 10680.79 | K29: 11182.38 | L29: 11822.1 | M29: 12618.34 | N29: 13419.22 | O29: 13701.55 | P29: 14052.46 | Q29: 14490.15 | R29: 14967.33 | S29: 15636.19 | T29: 16013.3 | U29: 16600.74 | V29: 17280.42 | W29: 17925.11 | X29: 18568.23 | Y29: 18399.41 | Z29: 18614.34 | AA29: 18911.08 | AB29: 19537.28 | AC29: 20350.73 | AD29: 21717.59
A30: agrr_ceic | B30: South Papua | C30: Papua Selatan | D30: Papua | AA30: 4201.92 | AB30: 4345.1 | AC30: 4444.51 | AD30: 4652.05
A31: agrr_ceic | B31: South Sulawesi | C31: Sulawesi Selatan | D31: Sulawesi Selatan | E31: 33353.51 | F31: 33671.01 | G31: 35218.73 | H31: 35478.6 | I31: 35240.91 | J31: 32427.95 | K31: 33757.98 | L31: 34842.74 | M31: 36963.89 | N31: 38695.1 | O31: 39598.91 | P31: 42325.57 | Q31: 44263.48 | R31: 46446.73 | S31: 51101.68 | T31: 54099.1 | U31: 58351.27 | V31: 61597.2 | W31: 64815.46 | X31: 66615.94 | Y31: 66139.9 | Z31: 70357.8 | AA31: 72162.73 | AB31: 72226.31 | AC31: 75166.74 | AD31: 80474.87
A32: agrr_ceic | B32: South Sumatera | C32: Sumatera Selatan | D32: Sumatera Selatan | E32: 23259.1 | F32: 24246.67 | G32: 25345.81 | H32: 26609.16 | I32: 28243.27 | J32: 29902.61 | K32: 31828.85 | L32: 33891.45 | M32: 35276.2 | N32: 36371.82 | O32: 38067.01 | P32: 40120.77 | Q32: 42557.3 | R32: 44794.97 | S32: 46612.03 | T32: 48287.68 | U32: 48942.64 | V32: 49518.88 | W32: 50674.28 | X32: 52366.83 | Y32: 53281.53 | Z32: 54834.53 | AA32: 56926.73 | AB32: 58154.46 | AC32: 59555.29 | AD32: 63001.27
A33: agrr_ceic | B33: South West Papua | C33: Papua Barat Daya | D33: Papua Barat | AB33: 2834.43 | AC33: 2849.11 | AD33: 3000.25
A34: agrr_ceic | B34: West Java | C34: Jawa Barat | D34: Jawa Barat | E34: 60856.34 | F34: 67181.71 | G34: 66846.15 | H34: 68505.57 | I34: 72851.48 | J34: 73875.4 | K34: 73621.7 | L34: 75451.5 | M34: 78522.4 | N34: 88209.99 | O34: 89088.26 | P34: 88386.51 | Q34: 88409.46 | R34: 92390.13 | S34: 92653.58 | T34: 92802.8 | U34: 98096.58 | V34: 99669.37 | W34: 101752.2 | X34: 104596.75 | Y34: 107000.79 | Z34: 108406.55 | AA34: 113186.39 | AB34: 113308.41 | AC34: 115104.77 | AD34: 126696.51
A35: agrr_ceic | B35: West Kalimantan | C35: Kalimantan Barat | D35: Kalimantan Barat | E35: 14734.24 | F35: 14333.19 | G35: 15365.42 | H35: 15834.1 | I35: 16210.1 | J35: 16964.12 | K35: 17869.57 | L35: 18740.84 | M35: 19820.43 | N35: 20610.8 | O35: 21485.41 | P35: 22292.71 | Q35: 23201.41 | R35: 24401.6 | S35: 24967.38 | T35: 25571.67 | U35: 26618.92 | V35: 28357.68 | W35: 30209.4 | X35: 31956.43 | Y35: 32371.35 | Z35: 33811.57 | AA35: 34547.57 | AB35: 35108.57 | AC35: 36150.73 | AD35: 36926.67
A36: agrr_ceic | B36: West Nusa Tenggara | C36: Nusa Tenggara Barat | D36: Nusa Tenggara Barat | E36: 11680.7 | F36: 11610.91 | G36: 11756.51 | H36: 12301.62 | I36: 12624.99 | J36: 12746.37 | K36: 13113.49 | L36: 13493.58 | M36: 14239.44 | N36: 14743.1 | O36: 14939.02 | P36: 15691.91 | Q36: 16407.44 | R36: 16946.74 | S36: 17702.37 | T36: 18964.88 | U36: 19564.75 | V36: 20843.23 | W36: 21262.43 | X36: 21555.36 | Y36: 21466.1 | Z36: 21712.18 | AA36: 22187.32 | AB36: 22642.74 | AC36: 22992.48 | AD36: 24150
A37: agrr_ceic | B37: West Papua | C37: Papua Barat | D37: Papua Barat | G37: 3429.79 | H37: 3603.52 | I37: 3744.32 | J37: 3821.22 | K37: 3946.88 | L37: 4152.88 | M37: 4439.14 | N37: 4609.14 | O37: 4889.56 | P37: 4583.19 | Q37: 4785.62 | R37: 5090.42 | S37: 5343.52 | T37: 5482.57 | U37: 5598.84 | V37: 5926.64 | W37: 6058.67 | X37: 6273.1 | Y37: 6122.47 | Z37: 6182.41 | AA37: 6199.07 | AB37: 3304.15 | AC37: 3310.73 | AD37: 3350.82
A38: agrr_ceic | B38: West Sulawesi | C38: Sulawesi Barat | D38: Sulawesi Barat | J38: 5684.53 | K38: 5934.41 | L38: 6146.94 | M38: 6338.3 | N38: 6535.66 | O38: 7486.61 | P38: 8115.11 | Q38: 8709.5 | R38: 9207.15 | S38: 9753.26 | T38: 10313.54 | U38: 10734.08 | V38: 11433.15 | W38: 12131.88 | X38: 12692.97 | Y38: 12761.98 | Z38: 12910.29 | AA38: 13342.96 | AB38: 13878.49 | AC38: 14541.57 | AD38: 15421.69
A39: agrr_ceic | B39: West Sumatera | C39: Sumatera Barat | D39: Sumatera Barat | E39: 16086.3 | F39: 16870.1 | G39: 18196.02 | H39: 19586.71 | I39: 20720.73 | J39: 21784.17 | K39: 22874.96 | L39: 24011.55 | M39: 25325.98 | N39: 26205.69 | O39: 27277.72 | P39: 28535.02 | Q39: 29284.9 | R39: 30372.99 | S39: 32151.49 | T39: 33546.76 | U39: 34222.56 | V39: 35394.69 | W39: 36639.6 | X39: 37549.46 | Y39: 37993.39 | Z39: 38820.71 | AA39: 40188.63 | AB39: 41612.83 | AC39: 42467.73 | AD39: 44227.28
A40: expr_ceic | B40: Aceh | C40: Aceh | D40: Aceh | E40: 126799.83 | F40: 120175.9 | G40: 136014.13 | H40: 139803.4 | I40: 113537.39 | J40: 79008.045 | K40: 68539.979 | L40: 70084.721 | M40: 66412.571 | N40: 52053.677 | O40: 48794.255 | P40: 48189.041 | Q40: 49148.162 | R40: 48786.604 | S40: 47198.272 | T40: 45570.602 | U40: 46196.343 | V40: 50893.467 | W40: 52747.141 | X40: 52517.086 | Y40: 52072.394 | Z40: 54937.198 | AA40: 68395.63 | AB40: 76810.85 | AC40: 81753.39 | AD40: 88632.84
...

Sheet WIDE_CEIC
A1: prov | B1: prov_name | C1: indicator | D1: 2000 | E1: 2001 | F1: 2002 | G1: 2003 | H1: 2004 | I1: 2005 | J1: 2006 | K1: 2007 | L1: 2008 | M1: 2009 | N1: 2010 | O1: 2011 | P1: 2012 | Q1: 2013 | R1: 2014 | S1: 2015 | T1: 2016 | U1: 2017 | V1: 2018 | W1: 2019 | X1: 2020 | Y1: 2021 | Z1: 2022 | AA1: 2023 | AB1: 2024 | AC1: 2025
A2: =VLOOKUP(B2,Legend!$C$32:$D$66,2,FALSE) -> 11 | B2: Aceh | C2: agrr_ceic | D2: 21575.61 | E2: 20882.8 | F2: 21327.97 | G2: 22025.17 | H2: 23356.22 | I2: 22447.34 | J2: 22788.31 | K2: 23612.76 | L2: 23803.54 | M2: 24412.68 | N2: 25579.57 | O2: 26515.48 | P2: 27685.11 | Q2: 28980.43 | R2: 29690.56 | S2: 31186.38 | T2: 32355.09 | U2: 34052.85 | V2: 35426.16 | W2: 36626.71 | X2: 37899.52 | Y2: 37768.08 | Z2: 39005.09 | AA2: 41626.32 | AB2: 42121.38 | AC2: 43637.59
A3: =VLOOKUP(B3,Legend!$C$32:$D$66,2,FALSE) -> 12 | B3: Sumatera Utara | C3: agrr_ceic | D3: 57864.17 | E3: 60061.78 | F3: 61584.13 | G3: 63131.37 | H3: 65499.04 | I3: 67713.98 | J3: 69340.93 | K3: 72794.06 | L3: 77201.71 | M3: 80943.58 | N3: 85561.14 | O3: 90592.55 | P3: 95405.42 | Q3: 99894.57 | R3: 104262.83 | S3: 110066 | T3: 115179.69 | U3: 121300.04 | V3: 127202.65 | W3: 133726.02 | X3: 136327.03 | Y3: 141601.18 | Z3: 148721.97 | AA3: 153246.71 | AB3: 158940.62 | AC3: 166702.96
A4: =VLOOKUP(B4,Legend!$C$32:$D$66,2,FALSE) -> 13 | B4: Sumatera Barat | C4: agrr_ceic | D4: 16086.3 | E4: 16870.1 | F4: 18196.02 | G4: 19586.71 | H4: 20720.73 | I4: 21784.17 | J4: 22874.96 | K4: 24011.55 | L4: 25325.98 | M4: 26205.69 | N4: 27277.72 | O4: 28535.02 | P4: 29284.9 | Q4: 30372.99 | R4: 32151.49 | S4: 33546.76 | T4: 34222.56 | U4: 35394.69 | V4: 36639.6 | W4: 37549.46 | X4: 37993.39 | Y4: 38820.71 | Z4: 40188.63 | AA4: 41612.83 | AB4: 42467.73 | AC4: 44227.28
A5: =VLOOKUP(B5,Legend!$C$32:$D$66,2,FALSE) -> 14 | B5: Riau | C5: agrr_ceic | D5: 59133.63 | E5: 62824.44 | F5: 66608.53 | G5: 63611.7 | H5: 68065.58 | I5: 72673.07 | J5: 77010.89 | K5: 80739.72 | L5: 84607.9 | M5: 87757.75 | N5: 91152.77 | O5: 94307.4 | P5: 97910.95 | Q5: 102216.74 | R5: 108498.09 | S5: 108969.04 | T5: 113287.59 | U5: 119281.64 | V5: 124547.86 | W5: 129690.41 | X5: 135124.21 | Y5: 140717.74 | Z5: 144691.04 | AA5: 149361.11 | AB5: 152698.4 | AC5: 160178.56
A6: =VLOOKUP(B6,Legend!$C$32:$D$66,2,FALSE) -> 15 | B6: Jambi | C6: agrr_ceic | D6: 13821.41 | E6: 14334.5 | F6: 15029.5 | G6: 15563.87 | H6: 16354.9 | I6: 17108.3 | J6: 19047.67 | K6: 19917.72 | L6: 21056.68 | M6: 22458.21 | N6: 23627.24 | O6: 24744.88 | P6: 26429.05 | Q6: 28070.96 | R6: 31145.43 | S6: 32846.19 | T6: 34933.69 | U6: 36809.09 | V6: 38041.61 | W6: 39160.08 | X6: 39751.94 | Y6: 41209.13 | Z6: 43268.38 | AA6: 45698.37 | AB6: 47643.01 | AC6: 50259.68
A7: =VLOOKUP(B7,Legend!$C$32:$D$66,2,FALSE) -> 16 | B7: Sumatera Selatan | C7: agrr_ceic | D7: 23259.1 | E7: 24246.67 | F7: 25345.81 | G7: 26609.16 | H7: 28243.27 | I7: 29902.61 | J7: 31828.85 | K7: 33891.45 | L7: 35276.2 | M7: 36371.82 | N7: 38067.01 | O7: 40120.77 | P7: 42557.3 | Q7: 44794.97 | R7: 46612.03 | S7: 48287.68 | T7: 48942.64 | U7: 49518.88 | V7: 50674.28 | W7: 52366.83 | X7: 53281.53 | Y7: 54834.53 | Z7: 56926.73 | AA7: 58154.46 | AB7: 59555.29 | AC7: 63001.27
A8: =VLOOKUP(B8,Legend!$C$32:$D$66,2,FALSE) -> 17 | B8: Bengkulu | C8: agrr_ceic | D8: 5728.65 | E8: 5937.16 | F8: 6202.04 | G8: 6565.87 | H8: 6928.19 | I8: 7331.42 | J8: 7751.37 | K8: 8189.66 | L8: 8643.42 | M8: 9119.25 | N8: 9343.96 | O8: 9734.67 | P8: 10272.89 | Q8: 10687.21 | R8: 10950.44 | S8: 11197.98 | T8: 11551.54 | U8: 11929.47 | V8: 12309.49 | W8: 12747.26 | X8: 12795.99 | Y8: 13109.72 | Z8: 13699.33 | AA8: 13981.69 | AB8: 14341.27 | AC8: 14930.39
A9: =VLOOKUP(B9,Legend!$C$32:$D$66,2,FALSE) -> 18 | B9: Lampung | C9: agrr_ceic | D9: 36401.86 | E9: 37589.5 | F9: 38093.11 | G9: 39660.9 | H9: 41879.08 | I9: 43834.02 | J9: 46198.15 | K9: 48747.48 | L9: 50168.11 | M9: 51486.83 | N9: 52038.77 | O9: 54841.03 | P9: 56997.47 | Q9: 59636.49 | R9: 61595.15 | S9: 63745.49 | T9: 65730.54 | U9: 66297.14 | V9: 66941.02 | W9: 67848.65 | X9: 68312.25 | Y9: 67969.86 | Z9: 69317.66 | AA9: 69697.99 | AB9: 68339.77 | AC9: 72381.45
A10: =VLOOKUP(B10,Legend!$C$32:$D$66,2,FALSE) -> 19 | B10: Kep. Bangka Belitung | C10: agrr_ceic | D10: 3798.22 | E10: 4111.44 | F10: 4317.44 | G10: 4410.78 | H10: 4606.99 | I10: 4824.45 | J10: 5090.6 | K10: 5244.62 | L10: 5457.99 | M10: 5658.28 | N10: 6097.69 | O10: 6642.8 | P10: 7072.89 | Q10: 7557.66 | R10: 8254.34 | S10: 8743.51 | T10: 9123.19 | U10: 9095.69 | V10: 9589.72 | W10: 9862.83 | X10: 10666.36 | Y10: 10768.72 | Z10: 10875.68 | AA10: 11281.88 | AB10: 11634.94 | AC10: 12003.87
A11: =VLOOKUP(B11,Legend!$C$32:$D$66,2,FALSE) -> 21 | B11: Kep. Riau | C11: agrr_ceic | G11: 3288.86 | H11: 3476.17 | I11: 3663.79 | J11: 3862.14 | K11: 4105.26 | L11: 4261.11 | M11: 4324.91 | N11: 4506.56 | O11: 4683.47 | P11: 4794.17 | Q11: 5000.01 | R11: 5378.15 | S11: 5689.22 | T11: 6018.41 | U11: 5945.61 | V11: 5757.78 | W11: 5717.73 | X11: 5466.78 | Y11: 5322.05 | Z11: 5601.86 | AA11: 5687.64 | AB11: 5720.17 | AC11: 5919.88
A12: =VLOOKUP(B12,Legend!$C$32:$D$66,2,FALSE) -> 31 | B12: DKI Jakarta | C12: agrr_ceic | D12: 1640.57 | E12: 1594.77 | F12: 1448.79 | G12: 1221.17 | H12: 1205.61 | I12: 1218.29 | J12: 1232.01 | K12: 1251.06 | L12: 1260.72 | M12: 1265.06 | N12: 1275.63 | O12: 1277.28 | P12: 1319.31 | Q12: 1353.56 | R12: 1359.95 | S12: 1375.42 | T12: 1387.53 | U12: 1391.53 | V12: 1394.05 | W12: 1398.22 | X12: 1405.1 | Y12: 1463.34 | Z12: 1501.26 | AA12: 1443.04 | AB12: 1516.95 | AC12: 1561.67
A13: =VLOOKUP(B13,Legend!$C$32:$D$66,2,FALSE) -> 32 | B13: Jawa Barat | C13: agrr_ceic | D13: 60856.34 | E13: 67181.71 | F13: 66846.15 | G13: 68505.57 | H13: 72851.48 | I13: 73875.4 | J13: 73621.7 | K13: 75451.5 | L13: 78522.4 | M13: 88209.99 | N13: 89088.26 | O13: 88386.51 | P13: 88409.46 | Q13: 92390.13 | R13: 92653.58 | S13: 92802.8 | T13: 98096.58 | U13: 99669.37 | V13: 101752.2 | W13: 104596.75 | X13: 107000.79 | Y13: 108406.55 | Z13: 113186.39 | AA13: 113308.41 | AB13: 115104.77 | AC13: 126696.51
A14: =VLOOKUP(B14,Legend!$C$32:$D$66,2,FALSE) -> 33 | B14: Jawa Tengah | C14: agrr_ceic | D14: 74414.1 | E14: 75249.33 | F14: 78974.16 | G14: 77357.68 | H14: 81484.1 | I14: 85239.54 | J14: 88308.93 | K14: 90760.04 | L14: 93659.82 | M14: 97136.21 | N14: 99572.44 | O14: 103389.33 | P14: 106536.7 | Q14: 108832.11 | R14: 107793.38 | S14: 113826.3 | T14: 116331.12 | U14: 118450.17 | V14: 121554.48 | W14: 123150.02 | X14: 126111.76 | Y14: 127065.84 | Z14: 130762.52 | AA14: 131330.54 | AB14: 133162.54 | AC14: 139530.4
A15: =VLOOKUP(B15,Legend!$C$32:$D$66,2,FALSE) -> 34 | B15: DI Yogyakarta | C15: agrr_ceic | D15: 5533.2 | E15: 5759.8 | F15: 5860.64 | G15: 5886.44 | H15: 6095.14 | I15: 6360.34 | J15: 6602.23 | K15: 6655.05 | L15: 7035.5 | M15: 7272.59 | N15: 7252.6 | O15: 7134.68 | P15: 7500.73 | Q15: 7670.03 | R15: 7508.98 | S15: 7667.6 | T15: 7779.8 | U15: 7930.31 | V15: 8101.23 | W15: 8184.19 | X15: 8534.64 | Y15: 8638.19 | Z15: 9077.78 | AA15: 9194.03 | AB15: 9206.5 | AC15: 9791.84
A16: =VLOOKUP(B16,Legend!$C$32:$D$66,2,FALSE) -> 35 | B16: Jawa Timur | C16: agrr_ceic | D16: 104112.98 | E16: 105425.77 | F16: 107560.12 | G16: 109612.12 | H16: 112702.18 | I16: 116264.13 | J16: 118147.24 | K16: 121859.06 | L16: 125664.22 | M16: 130589.82 | N16: 133504.56 | O16: 138870.09 | P16: 146002.57 | Q16: 150463.72 | R16: 155783.96 | S16: 160889.4 | T16: 164762.91 | U16: 167360.57 | V16: 163799.94 | W16: 165951.23 | X16: 167631.24 | Y16: 170556.77 | Z16: 173747.56 | AA16: 177668.37 | AB16: 177809.47 | AC16: 186662.71
A17: =VLOOKUP(B17,Legend!$C$32:$D$66,2,FALSE) -> 36 | B17: Banten | C17: agrr_ceic | D17: 10985.99 | E17: 11506.54 | F17: 11692.12 | G17: 12037.69 | H17: 12287.14 | I17: 12614.58 | J17: 12535.72 | K17: 14118.95 | L17: 14569.42 | M17: 15354.49 | N17: 16737.61 | O17: 17242.08 | P17: 17793.38 | Q17: 18990.92 | R17: 19456.95 | S17: 20743.47 | T17: 22108.75 | U17: 23055.55 | V17: 23880.77 | W17: 24408.33 | X17: 25275.08 | Y17: 25416.58 | Z17: 26490.53 | AA17: 26531.3 | AB17: 26703.35 | AC17: 29266.23
A18: =VLOOKUP(B18,Legend!$C$32:$D$66,2,FALSE) -> 51 | B18: Bali | C18: agrr_ceic | D18: 10487.44 | E18: 11082.48 | F18: 11488.73 | G18: 11905.69 | H18: 12341.19 | I18: 12858.93 | J18: 13386.6 | K18: 14618.96 | L18: 14963.8 | M18: 15813.19 | N18: 16092.72 | O18: 16258.74 | P18: 16969.88 | Q18: 17343.29 | R18: 18151.21 | S18: 18637.35 | T18: 19295.7 | U18: 19821.71 | V18: 20760.22 | W18: 21479.55 | X18: 21269.19 | Y18: 21338.45 | Z18: 21157.3 | AA18: 21058.7 | AB18: 21586.55 | AC18: 21954.29
A19: =VLOOKUP(B19,Legend!$C$32:$D$66,2,FALSE) -> 52 | B19: Nusa Tenggara Barat | C19: agrr_ceic | D19: 11680.7 | E19: 11610.91 | F19: 11756.51 | G19: 12301.62 | H19: 12624.99 | I19: 12746.37 | J19: 13113.49 | K19: 13493.58 | L19: 14239.44 | M19: 14743.1 | N19: 14939.02 | O19: 15691.91 | P19: 16407.44 | Q19: 16946.74 | R19: 17702.37 | S19: 18964.88 | T19: 19564.75 | U19: 20843.23 | V19: 21262.43 | W19: 21555.36 | X19: 21466.1 | Y19: 21712.18 | Z19: 22187.32 | AA19: 22642.74 | AB19: 22992.48 | AC19: 24150
A20: =VLOOKUP(B20,Legend!$C$32:$D$66,2,FALSE) -> 53 | B20: Nusa Tenggara Timur | C20: agrr_ceic | D20: 10469.09 | E20: 10799.67 | F20: 11205.53 | G20: 11435.39 | H20: 11835.1 | I20: 11949.36 | J20: 12540.98 | K20: 12884.94 | L20: 13379.21 | M20: 13684.3 | N20: 13963.14 | O20: 14244.98 | P20: 14669.95 | Q20: 15069.63 | R20: 15613.95 | S20: 16123.17 | T20: 16512.69 | U20: 17328.87 | V20: 17837.81 | W20: 18496.01 | X20: 18680.64 | Y20: 19601.9 | Z20: 20341.73 | AA20: 20842.3 | AB20: 21224.74 | AC20: 21967.56
A21: =VLOOKUP(B21,Legend!$C$32:$D$66,2,FALSE) -> 61 | B21: Kalimantan Barat | C21: agrr_ceic | D21: 14734.24 | E21: 14333.19 | F21: 15365.42 | G21: 15834.1 | H21: 16210.1 | I21: 16964.12 | J21: 17869.57 | K21: 18740.84 | L21: 19820.43 | M21: 20610.8 | N21: 21485.41 | O21: 22292.71 | P21: 23201.41 | Q21: 24401.6 | R21: 24967.38 | S21: 25571.67 | T21: 26618.92 | U21: 28357.68 | V21: 30209.4 | W21: 31956.43 | X21: 32371.35 | Y21: 33811.57 | Z21: 34547.57 | AA21: 35108.57 | AB21: 36150.73 | AC21: 36926.67
A22: =VLOOKUP(B22,Legend!$C$32:$D$66,2,FALSE) -> 62 | B22: Kalimantan Tengah | C22: agrr_ceic | D22: 11342.89 | E22: 11846.56 | F22: 11594.9 | G22: 12535.97 | H22: 12561.59 | I22: 12695.63 | J22: 13122.8 | K22: 13175.81 | L22: 13118.8 | M22: 13541.43 | N22: 13935.36 | O22: 14165.41 | P22: 14536.58 | Q22: 15028.38 | R22: 16080.17 | S22: 17031.88 | T22: 17686.42 | U22: 18514.01 | V22: 19824.58 | W22: 21250.83 | X22: 21304.92 | Y22: 22073.16 | Z22: 22834.25 | AA22: 23830.77 | AB22: 24138.62 | AC22: 25090.12
A23: =VLOOKUP(B23,Legend!$C$32:$D$66,2,FALSE) -> 63 | B23: Kalimantan Selatan | C23: agrr_ceic | D23: 8386.9 | E23: 9058.77 | F23: 9309.45 | G23: 9585.57 | H23: 10161.95 | I23: 10680.79 | J23: 11182.38 | K23: 11822.1 | L23: 12618.34 | M23: 13419.22 | N23: 13701.55 | O23: 14052.46 | P23: 14490.15 | Q23: 14967.33 | R23: 15636.19 | S23: 16013.3 | T23: 16600.74 | U23: 17280.42 | V23: 17925.11 | W23: 18568.23 | X23: 18399.41 | Y23: 18614.34 | Z23: 18911.08 | AA23: 19537.28 | AB23: 20350.73 | AC23: 21717.59
A24: =VLOOKUP(B24,Legend!$C$32:$D$66,2,FALSE) -> 64 | B24: Kalimantan Timur | C24: agrr_ceic | D24: 16282.68 | E24: 16580.67 | F24: 17030 | G24: 17214.66 | H24: 17708.7 | I24: 18161.03 | J24: 18806.2 | K24: 19141.98 | L24: 19698.74 | M24: 19993.01 | N24: 21167.77 | O24: 22292.61 | P24: 23991.79 | Q24: 25535.67 | R24: 27267.2 | S24: 28506.91 | T24: 28639.4 | U24: 30261.4 | V24: 32140.16 | W24: 33355.19 | X24: 33026.69 | Y24: 33003.9 | Z24: 33712.58 | AA24: 34551.18 | AB24: 35368.75 | AC24: 38094.43
A25: =VLOOKUP(B25,Legend!$C$32:$D$66,2,FALSE) -> 65 | B25: Kalimantan Utara | C25: agrr_ceic | N25: 6235.36 | O25: 6676.56 | P25: 7130 | Q25: 7496.93 | R25: 8021.34 | S25: 8574.02 | T25: 9022 | U25: 9423 | V25: 9941.19 | W25: 10475.64 | X25: 10925.64 | Y25: 11300.51 | Z25: 11723.08 | AA25: 12229.92 | AB25: 12444.24 | AC25: 12767.3
A26: =VLOOKUP(B26,Legend!$C$32:$D$66,2,FALSE) -> 71 | B26: Sulawesi Utara | C26: agrr_ceic | D26: 7667.12 | E26: 7964.89 | F26: 8320.34 | G26: 8392.96 | H26: 8947.76 | I26: 9497.69 | J26: 9740.67 | K26: 10479.52 | L26: 11089.02 | M26: 11318.59 | N26: 12281.01 | O26: 12154.19 | P26: 12918.08 | Q26: 13765.3 | R26: 14243.12 | S26: 14605.52 | T26: 15141.89 | U26: 15814.32 | V26: 16367.26 | W26: 17320.48 | X26: 17705.45 | Y26: 18040.14 | Z26: 19187.16 | AA26: 20036.33 | AB26: 21113.98 | AC26: 22337.2
A27: =VLOOKUP(B27,Legend!$C$32:$D$66,2,FALSE) -> 72 | B27: Sulawesi Tengah | C27: agrr_ceic | D27: 10450.93 | E27: 11123.93 | F27: 11885.49 | G27: 12772.13 | H27: 13766.84 | I27: 14650.9 | J27: 15448.99 | K27: 16550.24 | L27: 17312.7 | M27: 18419.21 | N27: 19523.49 | O27: 20711.36 | P27: 21923.49 | Q27: 23163.93 | R27: 24728.72 | S27: 26297.82 | T27: 26929.49 | U27: 28131.33 | V27: 29340.85 | W27: 29995.99 | X27: 29593.65 | Y27: 30793.12 | Z27: 31639.57 | AA27: 32224.74 | AB27: 32848.02 | AC27: 34309.75
A28: =VLOOKUP(B28,Legend!$C$32:$D$66,2,FALSE) -> 73 | B28: Sulawesi Selatan | C28: agrr_ceic | D28: 33353.51 | E28: 33671.01 | F28: 35218.73 | G28: 35478.6 | H28: 35240.91 | I28: 32427.95 | J28: 33757.98 | K28: 34842.74 | L28: 36963.89 | M28: 38695.1 | N28: 39598.91 | O28: 42325.57 | P28: 44263.48 | Q28: 46446.73 | R28: 51101.68 | S28: 54099.1 | T28: 58351.27 | U28: 61597.2 | V28: 64815.46 | W28: 66615.94 | X28: 66139.9 | Y28: 70357.8 | Z28: 72162.73 | AA28: 72226.31 | AB28: 75166.74 | AC28: 80474.87
A29: =VLOOKUP(B29,Legend!$C$32:$D$66,2,FALSE) -> 74 | B29: Sulawesi Tenggara | C29: agrr_ceic | D29: 8231.62 | E29: 8673.44 | F29: 9302.72 | G29: 9875.04 | H29: 10649.04 | I29: 11385.14 | J29: 11905.93 | K29: 12572.51 | L29: 13205.9 | M29: 13566.97 | N29: 13741.14 | O29: 14007.46 | P29: 14625.41 | Q29: 15508.22 | R29: 16952.31 | S29: 16970.46 | T29: 18270.18 | U29: 19323.26 | V29: 20554.63 | W29: 21581.03 | X29: 21728.37 | Y29: 22247.11 | Z29: 23754.98 | AA29: 24779.74 | AB29: 25734.91 | AC29: 26698.67
A30: =VLOOKUP(B30,Legend!$C$32:$D$66,2,FALSE) -> 75 | B30: Gorontalo | C30: agrr_ceic | D30: 3287.79 | E30: 3519.47 | F30: 3826.86 | G30: 3998.73 | H30: 4125.14 | I30: 4432.57 | J30: 4784.47 | K30: 5134.78 | L30: 5548.66 | M30: 5742.5 | N30: 5977.73 | O30: 6321.23 | P30: 6763.85 | Q30: 7232.59 | R30: 7698.32 | S30: 8024.61 | T30: 8540.36 | U30: 9314.37 | V30: 10019.05 | W30: 10652.83 | X30: 10478.78 | Y30: 10663.64 | Z30: 10907.95 | AA30: 11365.5 | AB30: 11719.48 | AC30: 12205.24
A31: =VLOOKUP(B31,Legend!$C$32:$D$66,2,FALSE) -> 76 | B31: Sulawesi Barat | C31: agrr_ceic | H31: 5507.7224 | I31: 5684.53 | J31: 5934.41 | K31: 6146.94 | L31: 6338.3 | M31: 6535.66 | N31: 7486.61 | O31: 8115.11 | P31: 8709.5 | Q31: 9207.15 | R31: 9753.26 | S31: 10313.54 | T31: 10734.08 | U31: 11433.15 | V31: 12131.88 | W31: 12692.97 | X31: 12761.98 | Y31: 12910.29 | Z31: 13342.96 | AA31: 13878.49 | AB31: 14541.57 | AC31: 15421.69
A32: =VLOOKUP(B32,Legend!$C$32:$D$66,2,FALSE) -> 81 | B32: Maluku | C32: agrr_ceic | D32: 3670.3 | E32: 3627.36 | F32: 3663.05 | G32: 3734.53 | H32: 3839.09 | I32: 3978.62 | J32: 4096.73 | K32: 4265.79 | L32: 4388.96 | M32: 4567.08 | N32: 4825.72 | O32: 4972.6 | P32: 5282.61 | Q32: 5500.92 | R32: 5835.44 | S32: 5908.36 | T32: 6188.01 | U32: 6558.6 | V32: 6858.55 | W32: 7230.24 | X32: 7353.71 | Y32: 7409.16 | Z32: 7833.24 | AA32: 8276.73 | AB32: 8557.59 | AC32: 9106.61
A33: =VLOOKUP(B33,Legend!$C$32:$D$66,2,FALSE) -> 82 | B33: Maluku Utara | C33: agrr_ceic | D33: 2514.56 | E33: 2562.49 | F33: 2645.37 | G33: 2768.44 | H33: 2848.76 | I33: 2974.86 | J33: 3116.28 | K33: 4102.26 | L33: 3936.69 | M33: 3739.01 | N33: 3936.69 | O33: 4105.56 | P33: 4371.36 | Q33: 4525.96 | R33: 4662.5 | S33: 4742.55 | T33: 4943.91 | U33: 5100.39 | V33: 5305.88 | W33: 5518.06 | X33: 5594.84 | Y33: 5727.23 | Z33: 5911.57 | AA33: 6162.71 | AB33: 6440.92 | AC33: 6646.89
A34: =VLOOKUP(B34,Legend!$C$32:$D$66,2,FALSE) -> 91 | B34: Papua Barat | C34: agrr_ceic | F34: 3429.79 | G34: 3603.52 | H34: 3744.32 | I34: 3821.22 | J34: 3946.88 | K34: 4152.88 | L34: 4439.14 | M34: 4609.14 | N34: 4889.56 | O34: 4583.19 | P34: 4785.62 | Q34: 5090.42 | R34: 5343.52 | S34: 5482.57 | T34: 5598.84 | U34: 5926.64 | V34: 6058.67 | W34: 6273.1 | X34: 6122.47 | Y34: 6182.41 | Z34: 6199.07 | AA34: 6138.58 | AB34: 6159.84 | AC34: 6351.07
A35: =VLOOKUP(B35,Legend!$C$32:$D$66,2,FALSE) -> 94 | B35: Papua | C35: agrr_ceic | D35: 11391.95 | E35: 12512.43 | F35: 8854.27 | G35: 9280.62 | H35: 9223.47 | I35: 9668.39 | J35: 10171.16 | K35: 10309.74 | L35: 10793.27 | M35: 11248.9 | N35: 11681.13 | O35: 12133.26 | P35: 12883.7 | Q35: 13661.8 | R35: 14432.99 | S35: 15192.6 | T35: 15461.69 | U35: 16070.49 | V35: 16602.56 | W35: 16608.11 | X35: 16490.61 | Y35: 16755.83 | Z35: 27384.44 | AA35: 17526.16 | AB35: 17793.55 | AC35: 18502.6
A36: =VLOOKUP(B36,Legend!$C$32:$D$66,2,FALSE) -> 11 | B36: Aceh | C36: expr_ceic | D36: 126799.83 | E36: 120175.9 | F36: 136014.13 | G36: 139803.4 | H36: 113537.39 | I36: 79008.045 | J36: 68539.979 | K36: 70084.721 | L36: 66412.571 | M36: 52053.677 | N36: 48794.255 | O36: 48189.041 | P36: 49148.162 | Q36: 48786.604 | R36: 47198.272 | S36: 45570.602 | T36: 46196.343 | U36: 50893.467 | V36: 52747.141 | W36: 52517.086 | X36: 52072.394 | Y36: 54937.198 | Z36: 68395.63 | AA36: 76810.85 | AB36: 81753.39 | AC36: 88632.84
A37: =VLOOKUP(B37,Legend!$C$32:$D$66,2,FALSE) -> 12 | B37: Sumatera Utara | C37: expr_ceic | D37: 66631.127 | E37: 75113.063 | F37: 76998.672 | G37: 80887.252 | H37: 99141.187 | I37: 105554.94 | J37: 101650.59 | K37: 111052.67 | L37: 122585.85 | M37: 121424.19 | N37: 133920.53 | O37: 155912.64 | P37: 159278.56 | Q37: 178463.32 | R37: 191872.58 | S37: 189848.62 | T37: 194929.51 | U37: 208689.48 | V37: 222718.56 | W37: 218152.13 | X37: 195680.31 | Y37: 223930.56 | Z37: 249627.87 | AA37: 248219.13 | AB37: 276532.14
A38: =VLOOKUP(B38,Legend!$C$32:$D$66,2,FALSE) -> 13 | B38: Sumatera Barat | C38: expr_ceic | D38: 14680.411 | E38: 15000.74 | F38: 17739.328 | G38: 20748.064 | H38: 26849.193 | I38: 32540.888 | J38: 38468.564 | K38: 49587.429 | L38: 60625.807 | M38: 61706.852 | N38: 72018.538 | O38: 81016.293 | P38: 132872.01 | Q38: 58747.116 | R38: 98028.053 | S38: 91332.179 | T38: 92501.782 | U38: 99153.079 | V38: 104226.87 | W38: 106852.6 | X38: 88163.434 | Y38: 92692.873 | Z38: 98839.35 | AA38: 106870.42 | AB38: 122494.07
A39: =VLOOKUP(B39,Legend!$C$32:$D$66,2,FALSE) -> 14 | B39: Riau | C39: expr_ceic | D39: 227774.34 | E39: 335229.79 | F39: 289578.7 | G39: 186245.16 | H39: 189927.1 | I39: 199143.25 | J39: 207868.62 | K39: 220898.35 | L39: 235674.78 | M39: 226771.24 | N39: 229801.07 | O39: 268075.13 | P39: 293195.74 | Q39: 285085.39 | R39: 242929.36 | S39: 200076.98 | T39: 179832.76 | U39: 205304.96 | V39: 209526.11 | W39: 213493.49 | X39: 225753.45 | Y39: 289376.88 | Z39: 336936.21 | AA39: 347466.91 | AB39: 353960.03
A40: =VLOOKUP(B40,Legend!$C$32:$D$66,2,FALSE) -> 15 | B40: Jambi | C40: expr_ceic | D40: 27406.778 | E40: 29184.503 | F40: 29208.938 | G40: 28964.155 | H40: 30716.31 | I40: 34709.889 | J40: 39551.498 | K40: 47189.309 | L40: 48943.841 | M40: 54293.165 | N40: 73721.858 | O40: 76468.471 | P40: 72869.868 | Q40: 76358.625 | R40: 80931.574 | S40: 88473.649 | T40: 91157.01 | U40: 100551.44 | V40: 108691.61 | W40: 112297.08 | X40: 101607.31 | Y40: 106352.4 | Z40: 110836.94 | AA40: 108965.38 | AB40: 112821.18
...

Sheet WIDE_IDD
A1: provname | B1: indicator | C1: 2000 | D1: 2001 | E1: 2002 | F1: 2003 | G1: 2004 | H1: 2005 | I1: 2006 | J1: 2007 | K1: 2008 | L1: 2009 | M1: 2010 | N1: 2011 | O1: 2012 | P1: 2013
A2: Aceh | B2: gdpn_idd | C2: 76927900 | D2: 73661657 | E2: 84860808 | F2: 94463588 | G2: 98324161 | H2: 107169006 | I2: 127277138 | J2: 132952788 | K2: 142309062 | L2: 141927835 | M2: 153993638 | N2: 158088777 | O2: 173424078 | P2: 85019450
A3: Bali | B3: gdpn_idd | C3: 33392042 | D3: 38848782 | E3: 45342118 | F3: 49868057 | G3: 55366698 | H3: 64940206 | I3: 71584693 | J3: 80972447 | K3: 95345888 | L3: 110340124 | M3: 124787185 | N3: 140401198 | O3: 158653244 | P3: 82879460
A4: Banten | B4: gdpn_idd | C4: 93053281 | D4: 106774418 | E4: 123289889 | F4: 136402054 | G4: 151188431 | H4: 173062572 | I4: 199167110 | J4: 220137615 | K4: 251336567 | L4: 283101307 | M4: 319123729 | N4: 383103940 | O4: 425656580 | P4: 241930320
A5: Bengkulu | B5: gdpn_idd | C5: 9737712 | D5: 10997303 | E5: 12524790 | F5: 14438085 | G5: 16109577 | H5: 20006638 | I5: 22520232 | J5: 25287103 | K5: 29143435 | L5: 31457669 | M5: 35464174 | N5: 40884468 | O5: 46261802 | P5: 24967840
A6: DI Yogyakarta | B6: gdpn_idd | C6: 27040431 | D6: 30627237 | E6: 35059556 | F6: 39262183 | G6: 43965765 | H6: 50583928 | I6: 58599125 | J6: 65443030 | K6: 75312922 | L6: 81939970 | M6: 90262920 | N6: 101060360 | O6: 111459733 | P6: 61361580
A7: DKI Jakarta | B7: gdpn_idd | C7: 455893455 | D7: 526315985 | E7: 598534894 | F7: 668891340 | G7: 752089786 | H7: 867058392 | I7: 998836906 | J7: 1137022999 | K7: 1358898596 | L7: 1516371414 | M7: 1720819681 | N7: 1954534869 | O7: 2198069942 | P7: 1246043880
A8: Gorontalo | B8: gdpn_idd | C8: 2950048 | D8: 3628484 | E8: 4333744 | F8: 4974964 | G8: 5616090 | H8: 6699786 | I8: 7761824 | J8: 9081042 | K8: 11235068 | L8: 13504394 | M8: 15439083 | N8: 17554979 | O8: 19933660 | P8: 10851960
A9: Jambi | B9: gdpn_idd | C9: 19066013 | D9: 22883691 | E9: 27462722 | F9: 32070335 | G9: 37384606 | H9: 44782524 | I9: 51943454 | J9: 62637380 | K9: 78770902 | L9: 87447756 | M9: 104972203 | N9: 112145094 | O9: 128887105 | P9: 65781080
A10: Jawa Barat | B10: gdpn_idd | C10: 383184616 | D10: 432406312 | E10: 484987430 | F10: 545148335 | G10: 611328267 | H10: 759340367 | I10: 912479126 | J10: 1024543911 | K10: 1206158051 | L10: 1320636434 | M10: 1479582025 | N10: 1616789512 | O10: 1783170551 | P10: 949518710
A11: Jawa Tengah | B11: gdpn_idd | C11: 221642824 | D11: 258621105 | E11: 297722756 | F11: 334652104 | G11: 373918059 | H11: 455833821 | I11: 538281577 | J11: 595907520 | K11: 698043649 | L11: 756174884 | M11: 842622258 | N11: 880683604 | O11: 980069682 | P11: 474109480
A12: Jawa Timur | B12: gdpn_idd | C12: 396109803 | D12: 453373953 | E12: 513473583 | F12: 576991767 | G12: 653793451 | H12: 775113615 | I12: 901653910 | J12: 1024648174 | K12: 1216193713 | L12: 1350533088 | M12: 1535135402 | N12: 1730001376 | O12: 1959479709 | P12: 1094387400
... A50: Kalimantan Timur | B50: gfcn_idd | C50: 8906808 | D50: 11718497 | E50: 13751361 | F50: 16362774 | G50: 18487192 | H50: 20886840 | I50: 24429058 | J50: 28331856 | K50: 35639764 | L50: 39242630 | M50: 44923631 | N50: 51476523 | O50: 60678389 | P50: 67488858
A51: Kalimantan Utara | B51: gfcn_idd
A52: Kep. Bangka Belitung | B52: gfcn_idd | C52: 948340 | D52: 1221073 | E52: 1320397 | F52: 1679193 | G52: 2706302 | H52: 3533109 | I52: 3793831 | J52: 4474760 | K52: 5588608 | L52: 6135023 | M52: 6826796 | N52: 7811270 | O52: 9235284 | P52: 10519079
A53: Kep. Riau | B53: gfcn_idd | C53: 11508795 | D53: 21345819 | E53: 26514246 | F53: 17781370 | G53: 18271618 | H53: 10470060 | I53: 13249338 | J53: 18464500 | K53: 28630934 | L53: 38169644 | M53: 51149983 | N53: 60223260 | O53: 72974470 | P53: 84252083
A54: Lampung | B54: gfcn_idd | C54: 4279942 | D54: 4553366 | E54: 4969997 | F54: 5323225 | G54: 5807551 | H54: 7379052 | I54: 8586097 | J54: 10127981 | K54: 13548673 | L54: 16299817 | M54: 18667584 | N54: 22130674 | O54: 25656641 | P54: 28983843
A55: Maluku | B55: gfcn_idd | C55: 76088 | D55: 86020 | E55: 144446 | F55: 160598 | G55: 192439 | H55: 209535 | I55: 244851 | J55: 326074 | K55: 380001 | L55: 421152 | M55: 509177 | N55: 625025 | O55: 818723 | P55: 937987
A56: Maluku Utara | B56: gfcn_idd | C56: 56155 | D56: 73955 | E56: 88988 | F56: 75126 | G56: 84301 | H56: 135748 | I56: 186402 | J56: 230930 | K56: 323630 | L56: 447619 | M56: 507019 | N56: 592832 | O56: 697330 | P56: 788003
A57: Nusa Tenggara Barat | B57: gfcn_idd | C57: 2858397 | D57: 3319583 | E57: 3713772 | F57: 4087296 | G57: 4601038 | H57: 5246875 | I57: 6070618 | J57: 7535111 | K57: 8845079 | L57: 11056066 | M57: 10809511 | N57: 12137547 | O57: 15370638 | P57: 16406323
A58: Nusa Tenggara Timur | B58: gfcn_idd | C58: 1616969 | D58: 1760479 | E58: 1876279 | F58: 1279469 | G58: 1681351 | H58: 1631425 | I58: 2466224 | J58: 2672400 | K58: 2905363 | L58: 3702522 | M58: 4568456 | N58: 5488722 | O58: 6765611 | P58: 8068143
A59: Papua | B59: gfcn_idd | C59: 2067425 | D59: 2812365 | E59: 4166789 | F59: 5060131 | G59: 6484486 | H59: 7536927 | I59: 10397056 | J59: 13801150 | K59: 17231782 | L59: 20809024 | M59: 24592564 | N59: 27783953 | O59: 30980533 | P59: 34869111
A60: Papua Barat | B60: gfcn_idd | C60: 2191890 | D60: 2787255 | E60: 2003830 | F60: 2372554 | G60: 2674027 | H60: 2942651 | I60: 3159414 | J60: 3469303 | K60: 4609113 | L60: 5624236 | M60: 6590543 | N60: 7914283 | O60: 10051777 | P60: 12538321
A61: Riau | B61: gfcn_idd | C61: 5627211 | D61: 9590933 | E61: 10916734 | F61: 24468044 | G61: 30835472 | H61: 34875392 | I61: 39192964 | J61: 48317380 | K61: 61464688 | L61: 72806510 | M61: 88613094 | N61: 101465266 | O61: 114773158 | P61: 129263751
A62: Sulawesi Barat | B62: gfcn_idd | C62: 245855 | D62: 287429 | E62: 346995 | F62: 363255 | G62: 392308 | H62: 444784 | I62: 546300 | J62: 853979 | K62: 1365252 | L62: 1494343 | M62: 1517598 | N62: 1589846 | O62: 1726512 | P62: 1968919
